2020-04-25 20:40:42,629,7396,django.request,ERROR,log.py:228,Internal Server Error: /api/v1/menu/list/
Traceback (most recent call last):
  File "D:\Anaconda3\envs\test\lib\site-packages\django\core\handlers\exception.py", line 34, in inner
    response = get_response(request)
  File "D:\Anaconda3\envs\test\lib\site-packages\django\core\handlers\base.py", line 115, in _get_response
    response = self.process_exception_by_middleware(e, request)
  File "D:\Anaconda3\envs\test\lib\site-packages\django\core\handlers\base.py", line 113, in _get_response
    response = wrapped_callback(request, *callback_args, **callback_kwargs)
  File "D:\Anaconda3\envs\test\lib\site-packages\django\views\decorators\csrf.py", line 54, in wrapped_view
    return view_func(*args, **kwargs)
  File "D:\Anaconda3\envs\test\lib\site-packages\django\views\generic\base.py", line 71, in view
    return self.dispatch(request, *args, **kwargs)
  File "D:\Anaconda3\envs\test\lib\site-packages\rest_framework\views.py", line 507, in dispatch
    self.response = self.finalize_response(request, response, *args, **kwargs)
  File "D:\Anaconda3\envs\test\lib\site-packages\rest_framework\views.py", line 422, in finalize_response
    % type(response)
AssertionError: Expected a `Response`, `HttpResponse` or `HttpStreamingResponse` to be returned from the view, but received a `<class 'dict'>`
2020-04-25 20:40:46,866,7396,django.request,ERROR,log.py:228,Internal Server Error: /api/v1/menu/list/
Traceback (most recent call last):
  File "D:\Anaconda3\envs\test\lib\site-packages\django\core\handlers\exception.py", line 34, in inner
    response = get_response(request)
  File "D:\Anaconda3\envs\test\lib\site-packages\django\core\handlers\base.py", line 115, in _get_response
    response = self.process_exception_by_middleware(e, request)
  File "D:\Anaconda3\envs\test\lib\site-packages\django\core\handlers\base.py", line 113, in _get_response
    response = wrapped_callback(request, *callback_args, **callback_kwargs)
  File "D:\Anaconda3\envs\test\lib\site-packages\django\views\decorators\csrf.py", line 54, in wrapped_view
    return view_func(*args, **kwargs)
  File "D:\Anaconda3\envs\test\lib\site-packages\django\views\generic\base.py", line 71, in view
    return self.dispatch(request, *args, **kwargs)
  File "D:\Anaconda3\envs\test\lib\site-packages\rest_framework\views.py", line 507, in dispatch
    self.response = self.finalize_response(request, response, *args, **kwargs)
  File "D:\Anaconda3\envs\test\lib\site-packages\rest_framework\views.py", line 422, in finalize_response
    % type(response)
AssertionError: Expected a `Response`, `HttpResponse` or `HttpStreamingResponse` to be returned from the view, but received a `<class 'dict'>`
2020-04-25 20:40:46,867,7396,django.server,ERROR,basehttp.py:157,"GET /api/v1/menu/list/ HTTP/1.1" 500 16189
2020-04-25 20:40:56,879,7396,django.request,ERROR,log.py:228,Internal Server Error: /api/v1/menu/list/
Traceback (most recent call last):
  File "D:\Anaconda3\envs\test\lib\site-packages\django\core\handlers\exception.py", line 34, in inner
    response = get_response(request)
  File "D:\Anaconda3\envs\test\lib\site-packages\django\core\handlers\base.py", line 115, in _get_response
    response = self.process_exception_by_middleware(e, request)
  File "D:\Anaconda3\envs\test\lib\site-packages\django\core\handlers\base.py", line 113, in _get_response
    response = wrapped_callback(request, *callback_args, **callback_kwargs)
  File "D:\Anaconda3\envs\test\lib\site-packages\django\views\decorators\csrf.py", line 54, in wrapped_view
    return view_func(*args, **kwargs)
  File "D:\Anaconda3\envs\test\lib\site-packages\django\views\generic\base.py", line 71, in view
    return self.dispatch(request, *args, **kwargs)
  File "D:\Anaconda3\envs\test\lib\site-packages\rest_framework\views.py", line 507, in dispatch
    self.response = self.finalize_response(request, response, *args, **kwargs)
  File "D:\Anaconda3\envs\test\lib\site-packages\rest_framework\views.py", line 422, in finalize_response
    % type(response)
AssertionError: Expected a `Response`, `HttpResponse` or `HttpStreamingResponse` to be returned from the view, but received a `<class 'dict'>`
2020-04-25 20:41:04,320,7396,django.request,ERROR,log.py:228,Internal Server Error: /api/v1/menu/list/
Traceback (most recent call last):
  File "D:\Anaconda3\envs\test\lib\site-packages\django\core\handlers\exception.py", line 34, in inner
    response = get_response(request)
  File "D:\Anaconda3\envs\test\lib\site-packages\django\core\handlers\base.py", line 115, in _get_response
    response = self.process_exception_by_middleware(e, request)
  File "D:\Anaconda3\envs\test\lib\site-packages\django\core\handlers\base.py", line 113, in _get_response
    response = wrapped_callback(request, *callback_args, **callback_kwargs)
  File "D:\Anaconda3\envs\test\lib\site-packages\django\views\decorators\csrf.py", line 54, in wrapped_view
    return view_func(*args, **kwargs)
  File "D:\Anaconda3\envs\test\lib\site-packages\django\views\generic\base.py", line 71, in view
    return self.dispatch(request, *args, **kwargs)
  File "D:\Anaconda3\envs\test\lib\site-packages\rest_framework\views.py", line 507, in dispatch
    self.response = self.finalize_response(request, response, *args, **kwargs)
  File "D:\Anaconda3\envs\test\lib\site-packages\rest_framework\views.py", line 422, in finalize_response
    % type(response)
AssertionError: Expected a `Response`, `HttpResponse` or `HttpStreamingResponse` to be returned from the view, but received a `<class 'dict'>`
2020-05-09 19:54:14,521,16998,django.request,ERROR,log.py:228,Internal Server Error: /api/v1/singleapi/export_report/
Traceback (most recent call last):
  File "/Users/zhuzhanhao/opt/anaconda3/envs/py37/lib/python3.7/site-packages/django/core/handlers/exception.py", line 34, in inner
    response = get_response(request)
  File "/Users/zhuzhanhao/opt/anaconda3/envs/py37/lib/python3.7/site-packages/django/core/handlers/base.py", line 115, in _get_response
    response = self.process_exception_by_middleware(e, request)
  File "/Users/zhuzhanhao/opt/anaconda3/envs/py37/lib/python3.7/site-packages/django/core/handlers/base.py", line 113, in _get_response
    response = wrapped_callback(request, *callback_args, **callback_kwargs)
  File "/Users/zhuzhanhao/opt/anaconda3/envs/py37/lib/python3.7/site-packages/django/views/decorators/csrf.py", line 54, in wrapped_view
    return view_func(*args, **kwargs)
  File "/Users/zhuzhanhao/opt/anaconda3/envs/py37/lib/python3.7/site-packages/django/views/generic/base.py", line 71, in view
    return self.dispatch(request, *args, **kwargs)
  File "/Users/zhuzhanhao/opt/anaconda3/envs/py37/lib/python3.7/site-packages/rest_framework/views.py", line 505, in dispatch
    response = self.handle_exception(exc)
  File "/Users/zhuzhanhao/opt/anaconda3/envs/py37/lib/python3.7/site-packages/rest_framework/views.py", line 465, in handle_exception
    self.raise_uncaught_exception(exc)
  File "/Users/zhuzhanhao/opt/anaconda3/envs/py37/lib/python3.7/site-packages/rest_framework/views.py", line 476, in raise_uncaught_exception
    raise exc
  File "/Users/zhuzhanhao/opt/anaconda3/envs/py37/lib/python3.7/site-packages/rest_framework/views.py", line 502, in dispatch
    response = handler(request, *args, **kwargs)
  File "/Users/zhuzhanhao/AutomationTest/ApiTest/api/pyechartExport.py", line 38, in post
    .render("./../templates/pyechartReport.html")
  File "/Users/zhuzhanhao/opt/anaconda3/envs/py37/lib/python3.7/site-packages/pyecharts/charts/base.py", line 64, in render
    return engine.render(self, path, template_name, env, **kwargs)
  File "/Users/zhuzhanhao/opt/anaconda3/envs/py37/lib/python3.7/site-packages/pyecharts/render/engine.py", line 72, in render
    template_name=template_name, chart=chart, path=path, **kwargs
  File "/Users/zhuzhanhao/opt/anaconda3/envs/py37/lib/python3.7/site-packages/pyecharts/render/engine.py", line 55, in render_chart_to_file
    write_utf8_html_file(path, html)
  File "/Users/zhuzhanhao/opt/anaconda3/envs/py37/lib/python3.7/site-packages/pyecharts/render/engine.py", line 14, in write_utf8_html_file
    with open(file_name, "w+", encoding="utf-8") as html_file:
FileNotFoundError: [Errno 2] No such file or directory: './../templates/pyechartReport.html'
2020-05-09 19:54:14,524,16998,django.server,ERROR,basehttp.py:157,"POST /api/v1/singleapi/export_report/ HTTP/1.1" 500 17601
2020-05-09 19:58:08,901,17039,django.request,ERROR,log.py:228,Internal Server Error: /api/v1/singleapi/export_report/
Traceback (most recent call last):
  File "/Users/zhuzhanhao/opt/anaconda3/envs/py37/lib/python3.7/site-packages/django/core/handlers/exception.py", line 34, in inner
    response = get_response(request)
  File "/Users/zhuzhanhao/opt/anaconda3/envs/py37/lib/python3.7/site-packages/django/core/handlers/base.py", line 115, in _get_response
    response = self.process_exception_by_middleware(e, request)
  File "/Users/zhuzhanhao/opt/anaconda3/envs/py37/lib/python3.7/site-packages/django/core/handlers/base.py", line 113, in _get_response
    response = wrapped_callback(request, *callback_args, **callback_kwargs)
  File "/Users/zhuzhanhao/opt/anaconda3/envs/py37/lib/python3.7/site-packages/django/views/decorators/csrf.py", line 54, in wrapped_view
    return view_func(*args, **kwargs)
  File "/Users/zhuzhanhao/opt/anaconda3/envs/py37/lib/python3.7/site-packages/django/views/generic/base.py", line 71, in view
    return self.dispatch(request, *args, **kwargs)
  File "/Users/zhuzhanhao/opt/anaconda3/envs/py37/lib/python3.7/site-packages/rest_framework/views.py", line 505, in dispatch
    response = self.handle_exception(exc)
  File "/Users/zhuzhanhao/opt/anaconda3/envs/py37/lib/python3.7/site-packages/rest_framework/views.py", line 465, in handle_exception
    self.raise_uncaught_exception(exc)
  File "/Users/zhuzhanhao/opt/anaconda3/envs/py37/lib/python3.7/site-packages/rest_framework/views.py", line 476, in raise_uncaught_exception
    raise exc
  File "/Users/zhuzhanhao/opt/anaconda3/envs/py37/lib/python3.7/site-packages/rest_framework/views.py", line 502, in dispatch
    response = handler(request, *args, **kwargs)
  File "/Users/zhuzhanhao/AutomationTest/ApiTest/api/pyechartExport.py", line 38, in post
    .render("../templates/pyechartReport.html")
  File "/Users/zhuzhanhao/opt/anaconda3/envs/py37/lib/python3.7/site-packages/pyecharts/charts/base.py", line 64, in render
    return engine.render(self, path, template_name, env, **kwargs)
  File "/Users/zhuzhanhao/opt/anaconda3/envs/py37/lib/python3.7/site-packages/pyecharts/render/engine.py", line 72, in render
    template_name=template_name, chart=chart, path=path, **kwargs
  File "/Users/zhuzhanhao/opt/anaconda3/envs/py37/lib/python3.7/site-packages/pyecharts/render/engine.py", line 55, in render_chart_to_file
    write_utf8_html_file(path, html)
  File "/Users/zhuzhanhao/opt/anaconda3/envs/py37/lib/python3.7/site-packages/pyecharts/render/engine.py", line 14, in write_utf8_html_file
    with open(file_name, "w+", encoding="utf-8") as html_file:
FileNotFoundError: [Errno 2] No such file or directory: '../templates/pyechartReport.html'
2020-05-09 19:58:08,902,17039,django.server,ERROR,basehttp.py:157,"POST /api/v1/singleapi/export_report/ HTTP/1.1" 500 17421
2020-05-09 22:10:33,547,17644,django.request,ERROR,log.py:228,Internal Server Error: /api/v1/singleapi/export_report/
Traceback (most recent call last):
  File "/Users/zhuzhanhao/opt/anaconda3/envs/py37/lib/python3.7/site-packages/django/core/handlers/exception.py", line 34, in inner
    response = get_response(request)
  File "/Users/zhuzhanhao/opt/anaconda3/envs/py37/lib/python3.7/site-packages/django/core/handlers/base.py", line 115, in _get_response
    response = self.process_exception_by_middleware(e, request)
  File "/Users/zhuzhanhao/opt/anaconda3/envs/py37/lib/python3.7/site-packages/django/core/handlers/base.py", line 113, in _get_response
    response = wrapped_callback(request, *callback_args, **callback_kwargs)
  File "/Users/zhuzhanhao/opt/anaconda3/envs/py37/lib/python3.7/site-packages/django/views/decorators/csrf.py", line 54, in wrapped_view
    return view_func(*args, **kwargs)
  File "/Users/zhuzhanhao/opt/anaconda3/envs/py37/lib/python3.7/site-packages/django/views/generic/base.py", line 71, in view
    return self.dispatch(request, *args, **kwargs)
  File "/Users/zhuzhanhao/opt/anaconda3/envs/py37/lib/python3.7/site-packages/rest_framework/views.py", line 505, in dispatch
    response = self.handle_exception(exc)
  File "/Users/zhuzhanhao/opt/anaconda3/envs/py37/lib/python3.7/site-packages/rest_framework/views.py", line 465, in handle_exception
    self.raise_uncaught_exception(exc)
  File "/Users/zhuzhanhao/opt/anaconda3/envs/py37/lib/python3.7/site-packages/rest_framework/views.py", line 476, in raise_uncaught_exception
    raise exc
  File "/Users/zhuzhanhao/opt/anaconda3/envs/py37/lib/python3.7/site-packages/rest_framework/views.py", line 502, in dispatch
    response = handler(request, *args, **kwargs)
  File "/Users/zhuzhanhao/AutomationTest/ApiTest/api/pyechartExport.py", line 31, in post
    .add_xaxis("访问路径",url_list)
TypeError: add_xaxis() takes 2 positional arguments but 3 were given
2020-05-09 22:10:33,554,17644,django.server,ERROR,basehttp.py:157,"POST /api/v1/singleapi/export_report/ HTTP/1.1" 500 16780
